Workbook

Sheet Start
A1: GATE 2027 · CS · Final-120-Days Tracker
A2: Kalpa Labs · Kit v1.0 · personal licence
A4: How to use
A5: 1. Plan tab: pick your exam date (it will be on your admit card). The countdown and plan update every day.
A6: 2. Syllabus tab: mark each topic Not started / Learning / Done. When you mark Done, type the date: revision dates appear (1, 3, 7, 21 days).
A7: 3. Daily log tab: type the hours you studied each day. Your streak counts itself.
A8: 4. Week tab: your hours this week and what's due for revision.
A10: Not an official GATE product. Dates and syllabus: gate2027.iitm.ac.in. Yellow cells are yours; don't type over white ones.
A11: Kalpa Labs · Udyam UDYAM-TS-02-0382711 · aakhiil51458@gmail.com

Sheet Plan
A1: Countdown and plan
A2: Exam days: 6, 7, 13, 14, 20, 21 Feb 2027 (IIT Madras)
A4: My exam date | B4: 46424
A5: Today | B5: =TODAY()
A6: Days left | B6: =MAX(0,B4-B5)
A7: Topics done | B7: =COUNTIF(Syllabus!C:C,"Done")&" of "&COUNTA(Syllabus!B5:B200)
A8: Syllabus done | B8: =IF(COUNTA(Syllabus!B5:B200)=0,0,COUNTIF(Syllabus!C:C,"Done")/COUNTA(Syllabus!B5:B200))
A9: Hours I can study a day | B9: 5
A10: Topics left ÷ days left (topics a day) | B10: =IF(B6=0,0,ROUND((COUNTA(Syllabus!B5:B200)-COUNTIF(Syllabus!C:C,"Done"))/B6,2))
A11: Current streak (days) | B11: ='Daily log'!F3
A12: Revisions due today or overdue | B12: =COUNTIFS(Syllabus!F5:F200,"<="&TODAY(),Syllabus!C5:C200,"Done")

Sheet Syllabus
A1: Syllabus checklist · GATE 2027 CS
A2: Revised syllabus applied (2027 changes marked) · check gate2027.iitm.ac.in
A4: Subject | B4: Topic | C4: Status | D4: Done on | E4: Revisions done | F4: Next revision | G4: Due?
A5: Engineering Mathematics | B5: Discrete Mathematics: propositional and first-order logic | C5: Not started | E5: 0 | F5: =IF(AND(C5="Done",ISNUMBER(D5),E5<4),D5+CHOOSE(E5+1,1,3,7,21),"") | G5: =IF(F5="","",IF(F5<=TODAY(),"Revise","Later"))
A6: Engineering Mathematics | B6: Sets, relations, functions, partial orders, lattices | C6: Not started | E6: 0 | F6: =IF(AND(C6="Done",ISNUMBER(D6),E6<4),D6+CHOOSE(E6+1,1,3,7,21),"") | G6: =IF(F6="","",IF(F6<=TODAY(),"Revise","Later"))
A7: Engineering Mathematics | B7: Monoids, groups | C7: Not started | E7: 0 | F7: =IF(AND(C7="Done",ISNUMBER(D7),E7<4),D7+CHOOSE(E7+1,1,3,7,21),"") | G7: =IF(F7="","",IF(F7<=TODAY(),"Revise","Later"))
A8: Engineering Mathematics | B8: Graphs: connectivity, matching, colouring | C8: Not started | E8: 0 | F8: =IF(AND(C8="Done",ISNUMBER(D8),E8<4),D8+CHOOSE(E8+1,1,3,7,21),"") | G8: =IF(F8="","",IF(F8<=TODAY(),"Revise","Later"))
A9: Engineering Mathematics | B9: Combinatorics: counting, recurrences, generating functions | C9: Not started | E9: 0 | F9: =IF(AND(C9="Done",ISNUMBER(D9),E9<4),D9+CHOOSE(E9+1,1,3,7,21),"") | G9: =IF(F9="","",IF(F9<=TODAY(),"Revise","Later"))
A10: Engineering Mathematics | B10: Linear Algebra: matrices, determinants, systems of linear equations | C10: Not started | E10: 0 | F10: =IF(AND(C10="Done",ISNUMBER(D10),E10<4),D10+CHOOSE(E10+1,1,3,7,21),"") | G10: =IF(F10="","",IF(F10<=TODAY(),"Revise","Later"))
A11: Engineering Mathematics | B11: Eigenvalues and eigenvectors, LU decomposition | C11: Not started | E11: 0 | F11: =IF(AND(C11="Done",ISNUMBER(D11),E11<4),D11+CHOOSE(E11+1,1,3,7,21),"") | G11: =IF(F11="","",IF(F11<=TODAY(),"Revise","Later"))
A12: Engineering Mathematics | B12: Calculus: limits, continuity, differentiability, maxima and minima, mean value theorem, integration | C12: Not started | E12: 0 | F12: =IF(AND(C12="Done",ISNUMBER(D12),E12<4),D12+CHOOSE(E12+1,1,3,7,21),"") | G12: =IF(F12="","",IF(F12<=TODAY(),"Revise","Later"))
A13: Engineering Mathematics | B13: Probability: random variables, uniform, normal, exponential, Poisson, binomial | C13: Not started | E13: 0 | F13: =IF(AND(C13="Done",ISNUMBER(D13),E13<4),D13+CHOOSE(E13+1,1,3,7,21),"") | G13: =IF(F13="","",IF(F13<=TODAY(),"Revise","Later"))
A14: Engineering Mathematics | B14: Mean, median, mode, standard deviation; conditional probability, Bayes | C14: Not started | E14: 0 | F14: =IF(AND(C14="Done",ISNUMBER(D14),E14<4),D14+CHOOSE(E14+1,1,3,7,21),"") | G14: =IF(F14="","",IF(F14<=TODAY(),"Revise","Later"))
A15: Digital Logic | B15: Boolean algebra | C15: Not started | E15: 0 | F15: =IF(AND(C15="Done",ISNUMBER(D15),E15<4),D15+CHOOSE(E15+1,1,3,7,21),"") | G15: =IF(F15="","",IF(F15<=TODAY(),"Revise","Later"))
A16: Digital Logic | B16: Combinational circuits | C16: Not started | E16: 0 | F16: =IF(AND(C16="Done",ISNUMBER(D16),E16<4),D16+CHOOSE(E16+1,1,3,7,21),"") | G16: =IF(F16="","",IF(F16<=TODAY(),"Revise","Later"))
... A69: General Aptitude | B69: Spatial aptitude | C69: Not started | E69: 0 | F69: =IF(AND(C69="Done",ISNUMBER(D69),E69<4),D69+CHOOSE(E69+1,1,3,7,21),"") | G69: =IF(F69="","",IF(F69<=TODAY(),"Revise","Later"))
A71: When you revise a topic, add 1 to 'Revisions done' and type today's date in 'Done on'. After 4 revisions it's off the list.

Sheet Daily log
A1: Daily log
A2: Type the hours you studied · the streak counts consecutive days with hours > 0
A3: Total hours | B3: =SUM(B6:B126) | E3: Current streak | F3: =IFERROR(IF(N(INDEX(B6:B126,MATCH(TODAY(),A6:A126,0)))>0,INDEX(E6:E126,MATCH(TODAY(),A6:A126,0)),IF(MATCH(TODAY(),A6:A126,0)>1,INDEX(E6:E126,MATCH(TODAY(),A6:A126,0)-1),0)),0)
A5: Date | B5: Hours | C5: Subject (optional) | D5: Questions solved | E5: Streak
A6: =Plan!$B$4-120 | E6: =IF(N(B6)>0,1,0)
A7: =Plan!$B$4-119 | E7: =IF(N(B7)>0,E6+1,0)
A8: =Plan!$B$4-118 | E8: =IF(N(B8)>0,E7+1,0)
A9: =Plan!$B$4-117 | E9: =IF(N(B9)>0,E8+1,0)
A10: =Plan!$B$4-116 | E10: =IF(N(B10)>0,E9+1,0)
A11: =Plan!$B$4-115 | E11: =IF(N(B11)>0,E10+1,0)
A12: =Plan!$B$4-114 | E12: =IF(N(B12)>0,E11+1,0)
A13: =Plan!$B$4-113 | E13: =IF(N(B13)>0,E12+1,0)
A14: =Plan!$B$4-112 | E14: =IF(N(B14)>0,E13+1,0)
A15: =Plan!$B$4-111 | E15: =IF(N(B15)>0,E14+1,0)
A16: =Plan!$B$4-110 | E16: =IF(N(B16)>0,E15+1,0)
A17: =Plan!$B$4-109 | E17: =IF(N(B17)>0,E16+1,0)
A18: =Plan!$B$4-108 | E18: =IF(N(B18)>0,E17+1,0)
A19: =Plan!$B$4-107 | E19: =IF(N(B19)>0,E18+1,0)
A20: =Plan!$B$4-106 | E20: =IF(N(B20)>0,E19+1,0)
A21: =Plan!$B$4-105 | E21: =IF(N(B21)>0,E20+1,0)
A22: =Plan!$B$4-104 | E22: =IF(N(B22)>0,E21+1,0)
A23: =Plan!$B$4-103 | E23: =IF(N(B23)>0,E22+1,0)
A24: =Plan!$B$4-102 | E24: =IF(N(B24)>0,E23+1,0)
A25: =Plan!$B$4-101 | E25: =IF(N(B25)>0,E24+1,0)
A26: =Plan!$B$4-100 | E26: =IF(N(B26)>0,E25+1,0)
A27: =Plan!$B$4-99 | E27: =IF(N(B27)>0,E26+1,0)
A28: =Plan!$B$4-98 | E28: =IF(N(B28)>0,E27+1,0)
A29: =Plan!$B$4-97 | E29: =IF(N(B29)>0,E28+1,0)
A30: =Plan!$B$4-96 | E30: =IF(N(B30)>0,E29+1,0)
A31: =Plan!$B$4-95 | E31: =IF(N(B31)>0,E30+1,0)
A32: =Plan!$B$4-94 | E32: =IF(N(B32)>0,E31+1,0)
A33: =Plan!$B$4-93 | E33: =IF(N(B33)>0,E32+1,0)
A34: =Plan!$B$4-92 | E34: =IF(N(B34)>0,E33+1,0)
A35: =Plan!$B$4-91 | E35: =IF(N(B35)>0,E34+1,0)
A36: =Plan!$B$4-90 | E36: =IF(N(B36)>0,E35+1,0)
A37: =Plan!$B$4-89 | E37: =IF(N(B37)>0,E36+1,0)
A38: =Plan!$B$4-88 | E38: =IF(N(B38)>0,E37+1,0)
A39: =Plan!$B$4-87 | E39: =IF(N(B39)>0,E38+1,0)
A40: =Plan!$B$4-86 | E40: =IF(N(B40)>0,E39+1,0)
A41: =Plan!$B$4-85 | E41: =IF(N(B41)>0,E40+1,0)
...

Sheet Week
A1: This week
A2: Monday to Sunday of the current week
A4: Week starts | B4: =TODAY()-WEEKDAY(TODAY(),3)
A5: Hours studied this week | B5: =SUMIFS('Daily log'!B6:B126,'Daily log'!A6:A126,">="&B4,'Daily log'!A6:A126,"<"&B4+7)
A6: Target hours this week | B6: =Plan!B9*7
A7: Revisions due by Sunday | B7: =COUNTIFS(Syllabus!F5:F200,"<"&B4+7,Syllabus!C5:C200,"Done")
A8: Topics still not started | B8: =COUNTIF(Syllabus!C5:C200,"Not started")

Sheet Sources
A1: Sources and weights
A2: Checked 16 Oct 2026
A19: Exam dates and organising institute: IIT Madras press release, iitm.ac.in (GATE 2027: 6, 7, 13, 14, 20, 21 Feb 2027; syllabus revised for 2027).
A20: CS 2027 syllabus changes: aspirantmitraa.com summary; the official syllabus is on gate2027.iitm.ac.in (always check it).
A21: Subject marks 2023–2025: GO Classes, 'A Strategic Analysis of Subject-wise Weightage Trends in GATE CSE (2023-2025)'. Engineering Mathematics 10 / 13 / 12; General Aptitude 15 every year.
A22: Weights guide your time; any subject can carry more marks in 2027.
